INFO:tensorflow:Using config: {'_save_checkpoints_steps': None, '_keep_checkpoint_every_n_hours': 10000, '_tf_random_seed': 1, '_session_config': None, '_log_step_count_steps': 100, '_save_summary_steps': 100, '_save_checkpoints_secs': 1000000000.0, '_model_dir': '/tmp/resnet_model', '_keep_checkpoint_max': 5}
Starting a training cycle.
Traceback (most recent call last):
  File "imagenet_main.py", line 278, in <module>
    tf.app.run(argv=[sys.argv[0]] + unparsed)
  File "/apps/daint/UES/jenkins/6.0.UP04/gpu/easybuild/software/TensorFlow/1.3.0-CrayGNU-17.08-cuda-8.0-python3/lib/python3.5/site-packages/tensorflow/python/platform/app.py", line 48, in run
    _sys.exit(main(_sys.argv[:1] + flags_passthrough))
  File "imagenet_main.py", line 267, in main
    hooks=[logging_hook])
  File "/apps/daint/UES/jenkins/6.0.UP04/gpu/easybuild/software/TensorFlow/1.3.0-CrayGNU-17.08-cuda-8.0-python3/lib/python3.5/site-packages/tensorflow/python/estimator/estimator.py", line 241, in train
    loss = self._train_model(input_fn=input_fn, hooks=hooks)
  File "/apps/daint/UES/jenkins/6.0.UP04/gpu/easybuild/software/TensorFlow/1.3.0-CrayGNU-17.08-cuda-8.0-python3/lib/python3.5/site-packages/tensorflow/python/estimator/estimator.py", line 628, in _train_model
    input_fn, model_fn_lib.ModeKeys.TRAIN)
  File "/apps/daint/UES/jenkins/6.0.UP04/gpu/easybuild/software/TensorFlow/1.3.0-CrayGNU-17.08-cuda-8.0-python3/lib/python3.5/site-packages/tensorflow/python/estimator/estimator.py", line 499, in _get_features_and_labels_from_input_fn
    result = self._call_input_fn(input_fn, mode)
  File "/apps/daint/UES/jenkins/6.0.UP04/gpu/easybuild/software/TensorFlow/1.3.0-CrayGNU-17.08-cuda-8.0-python3/lib/python3.5/site-packages/tensorflow/python/estimator/estimator.py", line 585, in _call_input_fn
    return input_fn(**kwargs)
  File "imagenet_main.py", line 266, in <lambda>
    True, FLAGS.data_dir, FLAGS.batch_size, FLAGS.epochs_per_eval),
  File "imagenet_main.py", line 137, in input_fn
    dataset = tf.data.Dataset.from_tensor_slices(filenames(is_training, data_dir))
AttributeError: module 'tensorflow' has no attribute 'data'
