INFO:tensorflow:Using config: {'_keep_checkpoint_max': 5, '_session_config': None, '_keep_checkpoint_every_n_hours': 10000, '_save_summary_steps': 100, '_save_checkpoints_secs': 1000000000.0, '_tf_random_seed': 1, '_model_dir': '/tmp/resnet_model', '_save_checkpoints_steps': None}
Starting a training cycle.
Traceback (most recent call last):
  File "imagenet_main.py", line 278, in <module>
    tf.app.run(argv=[sys.argv[0]] + unparsed)
  File "/apps/daint/UES/jenkins/6.0.UP04/gpu/easybuild/software/TensorFlow/1.2.1-CrayGNU-17.08-cuda-8.0-python3/lib/python3.5/site-packages/tensorflow/python/platform/app.py", line 48, in run
    _sys.exit(main(_sys.argv[:1] + flags_passthrough))
  File "imagenet_main.py", line 267, in main
    hooks=[logging_hook])
  File "/apps/daint/UES/jenkins/6.0.UP04/gpu/easybuild/software/TensorFlow/1.2.1-CrayGNU-17.08-cuda-8.0-python3/lib/python3.5/site-packages/tensorflow/python/estimator/estimator.py", line 241, in train
    loss = self._train_model(input_fn=input_fn, hooks=hooks)
  File "/apps/daint/UES/jenkins/6.0.UP04/gpu/easybuild/software/TensorFlow/1.2.1-CrayGNU-17.08-cuda-8.0-python3/lib/python3.5/site-packages/tensorflow/python/estimator/estimator.py", line 558, in _train_model
    features, labels = input_fn()
  File "imagenet_main.py", line 266, in <lambda>
    True, FLAGS.data_dir, FLAGS.batch_size, FLAGS.epochs_per_eval),
  File "imagenet_main.py", line 137, in input_fn
    dataset = tf.data.Dataset.from_tensor_slices(filenames(is_training, data_dir))
AttributeError: module 'tensorflow' has no attribute 'data'
